Workbook

Sheet 材质编号
A1: 材质 | B1: 材质编号
A2: Ag | B2: 00001
A3: AgC3 | B3: 00002
A4: AgC4 | B4: 00003
A5: AgC5 | B5: 00004
A6: AgNi25C2 | B6: 00005
A7: AgNi10 | B7: 00006
A8: Ag15CuP | B8: 00007
A9: Ag25CuP | B9: 00008
A10: Ag50CuZn | B10: 00009
A11: AgC4(石墨烯) | B11: 00010
A12: AgCdO10 | B12: 00011
... A135: NiFe | B135: 00134
A136: 630 | B136: 00135
A137: H62 | B137: 00136
A138: H65 | B138: 00137
A139: C2801 | B139: 00138
A140: Ag/H65 | B140: 00139
A141: CuZn33 | B141: 00140
A142: H63 | B142: 00141
A143: H70 | B143: 00142
A144: H68 | B144: 00143
A145: H85 | B145: 00144
A146: H85-Y2 | B146: 00145
A147: QSn6.5-0.1 | B147: 00146
A148: QSn65-01 | B148: 00147
... A153: AgNi10/H65 | B153: 00152
A154: 304 | B154: 00153
A155: 316 | B155: 00154
A156: AgCdO10/CuSn6 | B156: 00155
A157: H90 | B157: 00156
A158: AgNi10/H90 | B158: 00157
A159: C17200 | B159: 00158
A160: C7025 | B160: 00159
A161: ST37-2G | B161: 00160
A162: HSn90-2 | B162: 00161
A163: 1Cr18Ni9（12Cr18Ni9） | B163: 00162
A164: QSi3-1 | B164: 00163
A165: 6J40 | B165: 00164
A166: AgCdO15/Ag/BZn15-20 | B166: 00165
...

Sheet 材质对应元素
A1: 材质 | B1: 材质编号 | C1: 元素名称 | D1: 含量 | E1: 元素编号
A2: Ag | B2: 00001 | C2: Ag | D2: 1 | E2: =VLOOKUP(C2,[1]表1!C:E,3,0) -> 10001
A3: AgC3 | B3: =VLOOKUP(A3,[1]材质编号!A:B,2,0) -> 00002 | C3: Ag | D3: 0.97 | E3: =VLOOKUP(C3,[1]表1!C:E,3,0) -> 10001
A4: AgC3 | B4: =VLOOKUP(A4,[1]材质编号!A:B,2,0) -> 00002 | C4: C | D4: 0.03 | E4: =VLOOKUP(C4,[1]表1!C:E,3,0) -> 10012
A5: AgC4 | B5: =VLOOKUP(A5,[1]材质编号!A:B,2,0) -> 00003 | C5: Ag | D5: 0.97 | E5: =VLOOKUP(C5,[1]表1!C:E,3,0) -> 10001
A6: AgC4 | B6: =VLOOKUP(A6,[1]材质编号!A:B,2,0) -> 00003 | C6: C | D6: 0.03 | E6: =VLOOKUP(C6,[1]表1!C:E,3,0) -> 10012
A7: AgC5 | B7: =VLOOKUP(A7,[1]材质编号!A:B,2,0) -> 00004 | C7: Ag | D7: 0.960369 | E7: =VLOOKUP(C7,[1]表1!C:E,3,0) -> 10001
A8: AgC5 | B8: =VLOOKUP(A8,[1]材质编号!A:B,2,0) -> 00004 | C8: C | D8: 0.039631 | E8: =VLOOKUP(C8,[1]表1!C:E,3,0) -> 10012
A9: AgNi25C2 | B9: =VLOOKUP(A9,[1]材质编号!A:B,2,0) -> 00005 | C9: C | D9: 0.01 | E9: =VLOOKUP(C9,[1]表1!C:E,3,0) -> 10012
A10: AgNi25C2 | B10: =VLOOKUP(A10,[1]材质编号!A:B,2,0) -> 00005 | C10: Ni | D10: 0.23 | E10: =VLOOKUP(C10,[1]表1!C:E,3,0) -> 10005
A11: AgNi25C2 | B11: =VLOOKUP(A11,[1]材质编号!A:B,2,0) -> 00005 | C11: Ag | D11: 0.76 | E11: =VLOOKUP(C11,[1]表1!C:E,3,0) -> 10001
A12: AgNi10 | B12: =VLOOKUP(A12,[1]材质编号!A:B,2,0) -> 00006 | C12: Ag | D12: 0.9 | E12: =VLOOKUP(C12,[1]表1!C:E,3,0) -> 10001
A13: AgNi10 | B13: =VLOOKUP(A13,[1]材质编号!A:B,2,0) -> 00006 | C13: Ni | D13: 0.1 | E13: =VLOOKUP(C13,[1]表1!C:E,3,0) -> 10005
A14: Ag15CuP | B14: =VLOOKUP(A14,[1]材质编号!A:B,2,0) -> 00007 | C14: Cu | D14: 0.8 | E14: =VLOOKUP(C14,[1]表1!C:E,3,0) -> 10002
... A352: NiFe | B352: =VLOOKUP(A352,[1]材质编号!A:B,2,0) -> 00134 | C352: Ni | D352: 0.5 | E352: =VLOOKUP(C352,[1]表1!C:E,3,0) -> 10005
A353: 630 | B353: =VLOOKUP(A353,[1]材质编号!A:B,2,0) -> 00135 | C353: 不锈钢 | D353: 1 | E353: =VLOOKUP(C353,[1]表1!C:E,3,0) -> 10027
A354: H62 | B354: =VLOOKUP(A354,[1]材质编号!A:B,2,0) -> 00136 | C354: Zn | D354: 0.38 | E354: =VLOOKUP(C354,[1]表1!C:E,3,0) -> 10003
A355: H62 | B355: =VLOOKUP(A355,[1]材质编号!A:B,2,0) -> 00136 | C355: Cu | D355: 0.62 | E355: =VLOOKUP(C355,[1]表1!C:E,3,0) -> 10002
A356: H65 | B356: =VLOOKUP(A356,[1]材质编号!A:B,2,0) -> 00137 | C356: Zn | D356: 0.35 | E356: =VLOOKUP(C356,[1]表1!C:E,3,0) -> 10003
A357: H65 | B357: =VLOOKUP(A357,[1]材质编号!A:B,2,0) -> 00137 | C357: Cu | D357: 0.65 | E357: =VLOOKUP(C357,[1]表1!C:E,3,0) -> 10002
A358: C2801 | B358: =VLOOKUP(A358,[1]材质编号!A:B,2,0) -> 00138 | C358: Cu | D358: 0.62 | E358: =VLOOKUP(C358,[1]表1!C:E,3,0) -> 10002
A359: C2801 | B359: =VLOOKUP(A359,[1]材质编号!A:B,2,0) -> 00138 | C359: Zn | D359: 0.38 | E359: =VLOOKUP(C359,[1]表1!C:E,3,0) -> 10003
A360: Ag/H65 | B360: =VLOOKUP(A360,[1]材质编号!A:B,2,0) -> 00139 | C360: Ag | D360: 0.082 | E360: =VLOOKUP(C360,[1]表1!C:E,3,0) -> 10001
A361: Ag/H65 | B361: =VLOOKUP(A361,[1]材质编号!A:B,2,0) -> 00139 | C361: Zn | D361: 0.3213 | E361: =VLOOKUP(C361,[1]表1!C:E,3,0) -> 10003
A362: Ag/H65 | B362: =VLOOKUP(A362,[1]材质编号!A:B,2,0) -> 00139 | C362: Cu | D362: 0.5967 | E362: =VLOOKUP(C362,[1]表1!C:E,3,0) -> 10002
A363: CuZn33 | B363: =VLOOKUP(A363,[1]材质编号!A:B,2,0) -> 00140 | C363: Cu | D363: 0.65 | E363: =VLOOKUP(C363,[1]表1!C:E,3,0) -> 10002
A364: CuZn33 | B364: =VLOOKUP(A364,[1]材质编号!A:B,2,0) -> 00140 | C364: Zn | D364: 0.35 | E364: =VLOOKUP(C364,[1]表1!C:E,3,0) -> 10003
A365: H63 | B365: =VLOOKUP(A365,[1]材质编号!A:B,2,0) -> 00141 | C365: Zn | D365: 0.35 | E365: =VLOOKUP(C365,[1]表1!C:E,3,0) -> 10003
... A388: AgNi10/H65 | B388: =VLOOKUP(A388,[1]材质编号!A:B,2,0) -> 00152 | C388: Zn | D388: 0.290838 | E388: =VLOOKUP(C388,[1]表1!C:E,3,0) -> 10003
A389: 304 | B389: =VLOOKUP(A389,[1]材质编号!A:B,2,0) -> 00153 | C389: 304 | D389: 1 | E389: =VLOOKUP(C389,[1]表1!C:E,3,0) -> 10042
A390: 316 | B390: =VLOOKUP(A390,[1]材质编号!A:B,2,0) -> 00154 | C390: 316 | D390: 1 | E390: =VLOOKUP(C390,[1]表1!C:E,3,0) -> 10028
A391: AgCdO10/CuSn6 | B391: =VLOOKUP(A391,[1]材质编号!A:B,2,0) -> 00155 | C391: Sn | D391: 0.029204 | E391: =VLOOKUP(C391,[1]表1!C:E,3,0) -> 10004
A392: AgCdO10/CuSn6 | B392: =VLOOKUP(A392,[1]材质编号!A:B,2,0) -> 00155 | C392: Cu | D392: 0.457522 | E392: =VLOOKUP(C392,[1]表1!C:E,3,0) -> 10002
A393: AgCdO10/CuSn6 | B393: =VLOOKUP(A393,[1]材质编号!A:B,2,0) -> 00155 | C393: Ag | D393: 0.468055 | E393: =VLOOKUP(C393,[1]表1!C:E,3,0) -> 10001
A394: AgCdO10/CuSn6 | B394: =VLOOKUP(A394,[1]材质编号!A:B,2,0) -> 00155 | C394: Cd | D394: 0.045219 | E394: =VLOOKUP(C394,[1]表1!C:E,3,0) -> 10017
A395: H90 | B395: =VLOOKUP(A395,[1]材质编号!A:B,2,0) -> 00156 | C395: Zn | D395: 0.1 | E395: =VLOOKUP(C395,[1]表1!C:E,3,0) -> 10003
A396: H90 | B396: =VLOOKUP(A396,[1]材质编号!A:B,2,0) -> 00156 | C396: Cu | D396: 0.9 | E396: =VLOOKUP(C396,[1]表1!C:E,3,0) -> 10002
A397: AgNi10/H90 | B397: =VLOOKUP(A397,[1]材质编号!A:B,2,0) -> 00157 | C397: Ag | D397: 0.0195 | E397: =VLOOKUP(C397,[1]表1!C:E,3,0) -> 10001
A398: AgNi10/H90 | B398: =VLOOKUP(A398,[1]材质编号!A:B,2,0) -> 00157 | C398: Ni | D398: 0.002167 | E398: =VLOOKUP(C398,[1]表1!C:E,3,0) -> 10005
A399: AgNi10/H90 | B399: =VLOOKUP(A399,[1]材质编号!A:B,2,0) -> 00157 | C399: Zn | D399: 0.097833 | E399: =VLOOKUP(C399,[1]表1!C:E,3,0) -> 10003
...
