Workbook

Sheet 元素单价
A1: 客户编号 | B1: 客户名称 | C1: 项次 | D1: 单个元素名称/所有元素 | E1: 网址 | F1: 网站名称 | G1: 取用规则 | H1: 升水价/手续费 | I1: 货币 | J1: 计价单位
C2: 1 | D2: Ag | E2: www.i001.com | H2: 0.02 | I2: RMB | J2: KG
C3: 2 | D3: QB235 | G3: 15 | I3: RMB | J3: KG

Sheet 客户料号与宏丰料号的关系
A1: 客户料号名称 | B1: 客户产品编号 | C1: 客户图号 | D1: 宏丰料号 | E1: 付款方式 | F1: 基础货币 | G1: 报价货币 | H1: 汇率
A2: Kontakt BG3 | B2: Y7-12288353 | C2: 2100-0271-0327-02 | D2: 3100370149 | G2: EURO | H2: 8.2355
A3: Kontakt BG3 - 5,5 mm | B3: Y7-12310623 | C3: 2100-0271-0322-01 | D3: 3100370150 | G3: EURO | H3: 8.2355
A4: SILCU 0,125X082mm 14mm 03 STRIPE | B4: S0820125 | D4: 3111190148 | G4: EURO | H4: 8.2355
A5: SILCU 0,160X082mm 14mm 03 STRIPE | B5: S0820160 | D5: 3111190272 | G5: EURO | H5: 8.2355
A6: SILCU 0,160X087mm 15mm 04 STRIPE | B6: S0870160 | D6: 3111190108 | G6: EURO | H6: 8.2355
A7: SILCU 0,102X087mm 7,56mm 05 STRIPE | B7: S0880102 | D7: 3111190145 | G7: EURO | H7: 8.2355
A8: SILCU 0,191X087mm 7,56mm 05 STRIPE | B8: S0880191 | D8: 3111190146 | G8: EURO | H8: 8.2355
A9: SILCU 0,125X091mm 14mm 05 STRIPE | B9: S0910125 | D9: 3111190106 | G9: EURO | H9: 8.2355
A10: SILCU 0,160X091mm 14mm 05 STRIPE | B10: S0910160 | D10: 3111190271 | G10: EURO | H10: 8.2355
A11: SILCU 0,160X094mm 12.52mm 06 STRIPE | B11: S0946160 | D11: 3111190585 | G11: EURO | H11: 8.2355
A12: SILCU 0,160X105mm 14mm 06 STRIPE | B12: S1050160 | D12: 3111190147 | G12: EURO | H12: 8.2355
A13: SILCU 0,125X091mm 14mm 05 STRIPE | B13: EV01300001 | D13: 3111190582 | G13: EURO | H13: 8.2355
A14: SILCU 0,160X106mm 15mm 06 STRIPE | B14: EV01400002 | D14: 3111190581 | G14: EURO | H14: 8.2355
A15: SILCU 0,125X082mm 14mm 03 STRIPE | B15: EV01400003 | D15: 3111190277 | G15: EURO | H15: 8.2355
A16: SILCU 0,160X094mm 12.52mm 06 STRIPE | B16: EV01400008 | D16: 3111190597 | G16: EURO | H16: 8.2355
A17: SILCU 0,090X94,6mm 12,52mm 06 STRIPE | B17: EV01300045 | D17: 3111190683 | G17: EURO | H17: 8.2355
B18: CN92314718015201 | C18: GZ-1210-0160-0154-01 | D18: 3120013625 | G18: RMB
B19: CN92314718015202 | C19: GZ-1210-0160-0154-02 | D19: 3120013626 | G19: RMB
B20: 145180200 | C20: CB1802 | D20: 3100580060 | G20: RMB
B21: Y7-10006464 | D21: 3100280160 | G21: RMB
B22: CN12265446 | C22: GZ-2100-0273-0336-01 | D22: 3120013627 | G22: RMB
B23: CN12265481 | C23: GZ-2100-0273-0351-00(k) | D23: 3120013644 | G23: RMB
B24: cn12265618 | C24: GZ-2100-0272-0324-01 | D24: 3120013972 | G24: RMB
B25: cn12265529 | C25: GZ-2100-0272-0339-01 | D25: 3120013973 | G25: RMB
B26: GZ2105000368 | C26: GZC-2100-0500-0368-00 | D26: 3120015381 | G26: RMB
B27: GZ2105000365 | C27: GZC-2100-0500-0365-00 | D27: 3121010326 | G27: RMB
B28: GZ2105000370 | C28: GZC-2100-0500-0370-00 | D28: 3120015382 | G28: RMB
B29: GZ2103950325 | C29: GZ-2100-0395-0325-00 | D29: 3120014648 | G29: RMB
B30: GZ2103950376 | C30: GZ-2100-0395-0376-00 | D30: 3120014617 | G30: RMB
B31: GZ2105020370 | C31: GZC-2100-0502-0370-00 | D31: 3121010325 | G31: RMB
B32: GZ2105020377 | C32: GZC-2100-0502-0377-00 | D32: 3120014647 | G32: RMB
B33: GZ2105020368 | C33: GZC-2100-0502-0368-00 | D33: 3120014616 | G33: RMB
... B36: GZ2105030380 | C36: GZC-2100-0503-0380-00 | D36: 3121010327 | G36: RMB

Sheet 物料与元素BOM
A1: 宏丰料号 | B1: 投入材质 | C1: 投入材质名称 | D1: 项次 | E1: 元素 | F1: 组成含量（%） | G1: 损耗率% | H1: 毛用量 | I1: 毛用量单位 | J1: 净用量 | K1: 净用量单位
A2: 3100370149 | C2: =VLOOKUP(CLEAN(A2),物料BOM!A:D,4,0) -> AgSnO2(12） | D2: 1 | E2: Ag | H2: 0.58982014 | I2: g | J2: 0.58982014 | K2: g
A3: 3100370149 | C3: =VLOOKUP(CLEAN(A3),物料BOM!A:D,4,0) -> AgSnO2(12） | D3: 2 | E3: Sn | H3: =H2/9 -> 0.065535571 | I3: g | J3: =J2/9 -> 0.065535571 | K3: g
A4: 3100370150 | C4: =VLOOKUP(CLEAN(A4),物料BOM!A:D,4,0) -> AgSnO2(12） | D4: 1 | E4: Ag | H4: 0.36746801 | I4: g | J4: 0.36746801 | K4: g
A5: 3100370150 | C5: =VLOOKUP(CLEAN(A5),物料BOM!A:D,4,0) -> AgSnO2(12） | D5: 2 | E5: Sn | H5: =H4/9 -> 0.040829779 | I5: g | J5: =J4/9 -> 0.040829779 | K5: g
A6: 3111190106 | C6: =VLOOKUP(CLEAN(A6),物料BOM!A:D,4,0) -> Cu/Ag/Cu | D6: 2 | E6: Cu | G6: 2 | H6: 827.95437 | J6: 811.71997 | K6: g
A7: 3100580060 | C7: =VLOOKUP(CLEAN(A7),物料BOM!A:D,4,0) -> AgWC40 | D7: 1 | E7: Ag | H7: 0.45 | I7: g/pcs | J7: 0.45 | K7: g/pcs
A8: 3100580060 | C8: =VLOOKUP(CLEAN(A8),物料BOM!A:D,4,0) -> AgWC40 | D8: 2 | E8: WC | H8: 0.31923077 | I8: g/pcs | J8: 0.45 | K8: g/pcs
A9: 3100280160 | C9: =VLOOKUP(CLEAN(A9),物料BOM!A:D,4,0) -> AgNi10 | D9: 1 | E9: Ag | H9: 0.92 | I9: g/pcs | J9: 0.92 | K9: g/pcs
A10: 3100280160 | C10: =VLOOKUP(CLEAN(A10),物料BOM!A:D,4,0) -> AgNi10 | D10: 2 | E10: Ni | H10: =H9/9 -> 0.10222222 | I10: g/pcs | J10: =J9/9 -> 0.10222222 | K10: g/pcs
A11: 3120013625 | C11: =VLOOKUP(CLEAN(A11),物料BOM!A:D,4,0) -> AgNi20-Fe | D11: 1 | E11: Ag | H11: 32 | I11: g/Kpcs | J11: 32 | K11: g/Kpcs
A12: 3120013625 | C12: =VLOOKUP(CLEAN(A12),物料BOM!A:D,4,0) -> AgNi20-Fe | D12: 2 | E12: Ni | H12: 7 | I12: g/Kpcs | J12: 7 | K12: g/Kpcs
A13: 3120013626 | C13: =VLOOKUP(CLEAN(A13),物料BOM!A:D,4,0) -> AgNi15-T2 | D13: 1 | E13: Ag | H13: 59 | I13: g/Kpcs | J13: 59 | K13: g/Kpcs
A14: 3120013625 | C14: =VLOOKUP(CLEAN(A14),物料BOM!A:D,4,0) -> AgNi20-Fe | D14: 2 | E14: QB235 | H14: 0.9 | I14: g/pcs | J14: 0.9 | K14: g/pcs
A15: 3120013626 | C15: =VLOOKUP(CLEAN(A15),物料BOM!A:D,4,0) -> AgNi15-T2 | D15: 2 | E15: Cu | H15: 1.1 | I15: g/pcs | J15: 1.1 | K15: g/pcs
A16: 3111190106 | C16: =VLOOKUP(CLEAN(A16),物料BOM!A:D,4,0) -> Cu/Ag/Cu | D16: 1 | E16: Ag | G16: 1.5 | H16: 191.10423 | J16: 188.28003 | K16: 2.8242005
A17: 3111190108 | C17: =VLOOKUP(CLEAN(A17),物料BOM!A:D,4,0) -> Cu/Ag/Cu | D17: 2 | E17: Cu | G17: 2 | H17: 858.56005 | J17: 841.72554 | K17: 16.834511
A18: 3111190108 | C18: =VLOOKUP(CLEAN(A18),物料BOM!A:D,4,0) -> Cu/Ag/Cu | D18: 1 | E18: Ag | G18: 1.5 | H18: 160.64858 | J18: 158.27446 | K18: 2.3741169
A19: 3111190145 | C19: =VLOOKUP(CLEAN(A19),物料BOM!A:D,4,0) -> Cu/Ag/Cu | D19: 2 | E19: Cu | G19: 2 | H19: 819.38362 | J19: 803.31727 | K19: 16.066345
A20: 3111190145 | C20: =VLOOKUP(CLEAN(A20),物料BOM!A:D,4,0) -> Cu/Ag/Cu | D20: 1 | E20: Ag | G20: 1.5 | H20: 199.63297 | J20: 196.68273 | K20: 2.950241
A21: 3111190146 | C21: =VLOOKUP(CLEAN(A21),物料BOM!A:D,4,0) -> Cu/Ag/Cu | D21: 2 | E21: Cu | G21: 2 | H21: 819.38362 | J21: 803.31727 | K21: 16.066345
A22: 3111190146 | C22: =VLOOKUP(CLEAN(A22),物料BOM!A:D,4,0) -> Cu/Ag/Cu | D22: 1 | E22: Ag | G22: 1.5 | H22: 199.63297 | J22: 196.68273 | K22: 2.950241
A23: 3111190147 | C23: =VLOOKUP(CLEAN(A23),物料BOM!A:D,4,0) -> Cu/Ag/Cu | D23: 2 | E23: Cu | G23: 2 | H23: 820.49656 | J23: 804.4084 | K23: 16.088168
A24: 3111190147 | C24: =VLOOKUP(CLEAN(A24),物料BOM!A:D,4,0) -> Cu/Ag/Cu | D24: 1 | E24: Ag | G24: 1.5 | H24: 198.52548 | J24: 195.5916 | K24: 2.9338741
A25: 3111190148 | C25: =VLOOKUP(CLEAN(A25),物料BOM!A:D,4,0) -> Cu/Ag/Cu | D25: 2 | E25: Cu | G25: 2 | H25: 890.91487 | J25: 873.44595 | K25: 17.468919
A26: 3111190148 | C26: =VLOOKUP(CLEAN(A26),物料BOM!A:D,4,0) -> Cu/Ag/Cu | D26: 1 | E26: Ag | G26: 1.5 | H26: 128.45236 | J26: 126.55405 | K26: 1.8983107
A27: 3111190271 | C27: =VLOOKUP(CLEAN(A27),物料BOM!A:D,4,0) -> Cu/Ag/Cu | D27: 2 | E27: Cu | G27: 2 | H27: 827.95437 | J27: 811.71997 | K27: 16.234399
... A42: 3111190683 | C42: =VLOOKUP(CLEAN(A42),物料BOM!A:D,4,0) -> Cu/Ag/Cu | D42: 1 | E42: Ag | G42: 5 | H42: 273 | J42: 260 | K42: 13
A43: 3120014648 | C43: H65 | D43: 1 | E43: Zn | G43: 5 | H43: =J43*1.05 -> 0.97538969 | I43: g/pcs | J43: 0.92894256
A44: 3120014617 | C44: H65 | D44: 1 | E44: Zn | G44: 5 | H44: =J44*1.05 -> 0.97538969 | I44: g/pcs | J44: 0.92894256
A45: 3121010325 | C45: H65 | D45: 1 | E45: Zn | G45: 5 | H45: =J45*1.05 -> 0.1619352 | I45: g/pcs | J45: 0.154224
A46: 3120014647 | C46: H65 | D46: 1 | E46: Zn | G46: 5 | H46: =J46*1.05 -> 0.97217347 | I46: g/pcs | J46: 0.9258795
A47: 3120014616 | C47: H65 | D47: 1 | E47: Zn | G47: 5 | H47: =J47*1.05 -> 0.97217347 | I47: g/pcs | J47: 0.9258795
A48: 3120015383 | C48: H65 | D48: 1 | E48: Zn | G48: 5 | H48: =J48*1.05 -> 0.57909033 | I48: g/pcs | J48: 0.5515146
A49: 3120015380 | C49: H65 | D49: 1 | E49: Zn | G49: 5 | H49: =J49*1.05 -> 0.57909033 | I49: g/pcs | J49: 0.5515146
A50: 3120014648 | C50: H65 | D50: 2 | E50: Cu | G50: 5 | H50: =J50*1.05 -> 1.811438 | I50: g/pcs | J50: 1.725179
A51: 3120014617 | C51: H65 | D51: 2 | E51: Cu | G51: 5 | H51: =J51*1.05 -> 1.811438 | I51: g/pcs | J51: 1.725179
A52: 3121010325 | C52: H65 | D52: 2 | E52: Cu | G52: 5 | H52: =J52*1.05 -> 0.3007368 | I52: g/pcs | J52: 0.286416
A53: 3120014647 | C53: H65 | D53: 2 | E53: Cu | G53: 5 | H53: =J53*1.05 -> 1.805465 | I53: g/pcs | J53: 1.7194905
A54: 3120014616 | C54: H65 | D54: 2 | E54: Cu | G54: 5 | H54: =J54*1.05 -> 1.805465 | I54: g/pcs | J54: 1.7194905
...

Sheet 物料BOM
A1: 宏丰料号 | B1: 项次 | C1: 投入材质 | D1: 投入材质名称 | E1: 产出料号类型 | F1: 材料毛重 | G1: 材料净重 | H1: 重量单位 | I1: 损耗率（%） | J1: 不良率（%）
A2: 3100280160 | D2: AgNi10 | E2: AgNi10触点
A3: 3100370149 | D3: AgSnO2(12） | E3: AgSnO2(12)触点
A4: 3100370150 | D4: AgSnO2(12） | E4: AgSnO2(12)触点
A5: 3100580060 | D5: AgWC40 | E5: AgWC40触点
A6: 3111190106 | D6: Cu/Ag/Cu | E6: Cu/Ag/Cu带
A7: 3111190108 | D7: Cu/Ag/Cu | E7: Cu/Ag/Cu带
A8: 3111190145 | D8: Cu/Ag/Cu | E8: Cu/Ag/Cu带
A9: 3111190146 | D9: Cu/Ag/Cu | E9: Cu/Ag/Cu带
A10: 3111190147 | D10: Cu/Ag/Cu | E10: Cu/Ag/Cu带
A11: 3111190148 | D11: Cu/Ag/Cu | E11: Cu/Ag/Cu带
A12: 3111190271 | D12: Cu/Ag/Cu | E12: Cu/Ag/Cu带
A13: 3111190272 | D13: Cu/Ag/Cu | E13: Cu/Ag/Cu带
... A29: 3120014648 | D29: H65/AgSnO2(12） | E29: H65/AgSnO2(12)接触桥
A30: 3120015380 | C30: AgNi10/Cu-H65铆接件 | D30: AgNi10/Cu-H65 | E30: AgNi10/Cu-H65铆接件
A31: 3120015381 | C31: AgNi10/Cu-H65组件 | D31: AgNi10/Cu-H65 | E31: AgNi10/Cu-H65组件
A32: 3120015382 | C32: AgNi10/Cu-H65铆接件 | D32: AgNi10/Cu-H65 | E32: AgNi10/Cu-H65铆接件
A33: 3120015383 | C33: AgNi10/Cu-H65组件 | D33: AgNi10/Cu-H65 | E33: AgNi10/Cu-H65组件
A34: 3121010325 | C34: AgNi10/Cu-H65组件 | D34: AgNi10/Cu-H65 | E34: AgNi10/Cu-H65组件
A35: 3121010326 | C35: AgNi10/Cu-H65组件 | D35: AgNi10/Cu-H65 | E35: AgNi10/Cu-H65组件
A36: 3121010327 | C36: AgNi10/Cu-H65组件 | D36: AgNi10/Cu-H65 | E36: AgNi10/Cu-H65组件

Sheet 元素回收折扣
A1: 宏丰料号 | B1: 投入料号 | C1: 投入料号名称 | D1: 项次 | E1: 元素 | F1: 回收折扣（%）

Sheet 来料固定加工费
A1: 宏丰料号 | B1: 项次 | C1: 投入料号 | D1: 投入料号名称 | E1: 基准值 | F1: 比例（%） | G1: 货币 | H1: 计价单位 | I1: 是否随材料价格波动 | J1: 材料结算涨幅比例（%） | K1: 材料固定的涨幅值 | L1: 货币 | M1: 涨幅单位
A2: 3100370149 | B2: 1 | E2: 0.0728 | F2: 0.96 | G2: EURO | H2: Unit
A3: 3100370150 | B3: 1 | E3: 0.055 | F3: 0.96 | G3: EURO | H3: Unit
A4: 3111190106 | B4: 1 | E4: 600 | F4: 0.985*0.977*1.28 | G4: EURO | H4: Kg
A5: 3111190108 | B5: 1 | E5: 540 | F5: 0.985*0.977*1.28 | G5: EURO | H5: Kg
A6: 3111190145 | B6: 1 | E6: 600 | F6: 0.985*0.977*1.28 | G6: EURO | H6: Kg
A7: 3111190146 | B7: 1 | E7: 600 | F7: 0.985*0.977*1.28 | G7: EURO | H7: Kg
A8: 3111190147 | B8: 1 | E8: 580 | F8: 0.985*0.977*1.28 | G8: EURO | H8: Kg
A9: 3111190148 | B9: 1 | E9: 600 | F9: 0.985*0.977*1.28 | G9: EURO | H9: Kg
A10: 3111190271 | B10: 1 | E10: 580 | F10: 0.985*0.977*1.28 | G10: EURO | H10: Kg
A11: 3111190272 | B11: 1 | E11: 550 | F11: 0.985*0.977*1.28 | G11: EURO | H11: Kg
A12: 3111190277 | B12: 1 | E12: 600 | F12: 0.985*0.977*1.28 | G12: EURO | H12: Kg
A13: 3111190581 | B13: 1 | E13: 600 | F13: 1.28 | G13: EURO | H13: Kg
A14: 3111190582 | B14: 1 | E14: 600 | F14: 0.985*0.977*1.28 | G14: EURO | H14: Kg
A15: 3111190585 | B15: 1 | E15: 800 | F15: 0.985*0.977*1.28 | G15: EURO | H15: Kg
A16: 3111190597 | B16: 1 | E16: 800 | F16: 0.985*0.977*1.28 | G16: EURO | H16: Kg
A17: 3111190683 | B17: 1 | E17: 900 | F17: 1.28 | G17: EURO | H17: Kg
A18: 3100280160 | B18: 1 | E18: =200*0.982 -> 196.4 | G18: RMB | H18: pcs
A19: 3100580060 | B19: 1 | E19: =0.495*0.982 -> 0.48609 | G19: RMB | H19: pcs
A20: 3120014648 | B20: 1 | E20: 0.1749924 | G20: RMB | H20: pcs
A21: 3120014617 | B21: 1 | E21: 0.1749924 | G21: RMB | H21: pcs
A22: 3121010325 | B22: 1 | E22: 0.0291654 | G22: RMB | H22: pcs
A23: 3120014647 | B23: 1 | E23: 0.1749924 | G23: RMB | H23: pcs
A24: 3120014616 | B24: 1 | E24: 0.1749924 | G24: RMB | H24: pcs
A25: 3120015383 | B25: 1 | E25: 0.0437481 | G25: RMB | H25: pcs
A26: 3120015380 | B26: 1 | E26: 0.0194436 | G26: RMB | H26: pcs
A27: 3121010327 | B27: 1 | E27: 0.0194436 | G27: RMB | H27: pcs

Sheet 来料其他费用
A1: 宏丰料号 | B1: 项次 | C1: 投入料号 | D1: 投入料号名称 | E1: 项次 | F1: 要素名称 | G1: 值 | H1: 比例（%） | I1: 货币 | J1: 计价单位

Sheet 来料年降
A1: 宏丰料号 | B1: 项次 | C1: 投入料号 | D1: 投入料号名称 | E1: 年降顺序 | F1: 年降系数（%） | G1: 单次固定年降值 | H1: 货币 | I1: 计价单位 | J1: 降价次数

Sheet 来料回收折扣
A1: 宏丰料号 | B1: 项次 | C1: 投入料号 | D1: 投入料号名称 | E1: 回收折扣（%）

Sheet 自制加工费
A1: 宏丰料号 | B1: 项次 | C1: 投入料号 | D1: 投入料号名称 | E1: 项次 | F1: 工序编号 | G1: 工序名称 | H1: 值 | I1: 比例（%） | J1: 货币 | K1: 计价单位

Sheet 成品其他费用
A1: 宏丰料号 | B1: 项次 | C1: 要素名称 | D1: 值 | E1: 比例（%） | F1: 货币 | G1: 计价单位
A2: 3100370149 | B2: 1 | C2: 运费 | D2: 0.03 | F2: EURO | G2: Unit
A3: 3100370150 | B3: 1 | C3: 运费 | D3: 0.018 | F3: EURO | G3: Unit
A4: 3111190106 | B4: 1 | C4: 运费 | D4: 87 | F4: EURO | G4: Kg
A5: 3111190108 | B5: 1 | C5: 运费 | D5: 87 | F5: EURO | G5: Kg
A6: 3111190145 | B6: 1 | C6: 运费 | D6: 87 | F6: EURO | G6: Kg
A7: 3111190146 | B7: 1 | C7: 运费 | D7: 87 | F7: EURO | G7: Kg
A8: 3111190147 | B8: 1 | C8: 运费 | D8: 87 | F8: EURO | G8: Kg
A9: 3111190148 | B9: 1 | C9: 运费 | D9: 87 | F9: EURO | G9: Kg
A10: 3111190271 | B10: 1 | C10: 运费 | D10: 87 | F10: EURO | G10: Kg
A11: 3111190272 | B11: 1 | C11: 运费 | D11: 87 | F11: EURO | G11: Kg
A12: 3111190277 | B12: 1 | C12: 运费 | D12: 87 | F12: EURO | G12: Kg
A13: 3111190581 | B13: 1 | C13: 运费 | D13: 87 | F13: EURO | G13: Kg
A14: 3111190582 | B14: 1 | C14: 运费 | D14: 87 | F14: EURO | G14: Kg
A15: 3111190585 | B15: 1 | C15: 运费 | D15: 87 | F15: EURO | G15: Kg
... A17: 3111190683 | B17: 1 | C17: 运费 | D17: 87 | F17: EURO | G17: Kg
A18: 3120013625 | B18: 1 | C18: 焊接费 | D18: 0.0577416 | F18: RMB | G18: pcs
A19: 3120013626 | B19: 1 | C19: 焊接费 | D19: 0.0577416 | F19: RMB | G19: pcs
A20: 3120013627 | B20: 1 | C20: 焊接费 | D20: 0.0826353 | F20: RMB | G20: pcs
A21: 3120013644 | B21: 1 | C21: 焊接费 | D21: 0.0826353 | F21: RMB | G21: pcs
A22: 3120013972 | B22: 1 | C22: 焊接费 | D22: =0.085*0.99*0.982 -> 0.0826353 | F22: RMB | G22: pcs
A23: 3120013973 | B23: 1 | C23: 焊接费 | D23: =0.085*0.99*0.982 -> 0.0826353 | F23: RMB | G23: pcs
A24: 3120014616 | B24: 1 | C24: 焊接费 | D24: 0.2946 | F24: RMB | G24: pcs
A25: 3120014617 | B25: 1 | C25: 焊接费 | D25: 0.2946 | F25: RMB | G25: pcs
A26: 3120014616 | B26: 2 | C26: 包装和运输费 | D26: 0.03 | F26: RMB | G26: pcs
A27: 3120014617 | B27: 2 | C27: 包装和运输费 | D27: 0.03 | F27: RMB | G27: pcs
A28: 3120015381 | B28: 1 | C28: 铆接费 | D28: 0.0291654 | F28: RMB | G28: pcs
A29: 3121010326 | B29: 1 | C29: 铆接费 | D29: 0.0194436 | F29: RMB | G29: pcs
A30: 3120015382 | B30: 1 | C30: 铆接费 | D30: 0.0291654 | F30: RMB | G30: pcs
A31: 3120015381 | B31: 2 | C31: 包装和运输费 | D31: 0.02 | F31: RMB | G31: pcs
A32: 3121010326 | B32: 2 | C32: 包装和运输费 | D32: 0.02 | F32: RMB | G32: pcs
A33: 3120015382 | B33: 2 | C33: 包装和运输费 | D33: 0.02 | F33: RMB | G33: pcs
A34: 3120014648 | B34: 1 | C34: 包装和运输费 | D34: 0.02 | F34: RMB | G34: pcs
A35: 3120014617 | B35: 1 | C35: 包装和运输费 | D35: 0.02 | F35: RMB | G35: pcs
A36: 3121010325 | B36: 1 | C36: 包装和运输费 | D36: 0.02 | F36: RMB | G36: pcs
A37: 3120014647 | B37: 1 | C37: 包装和运输费 | D37: 0.02 | F37: RMB | G37: pcs
A38: 3120014616 | B38: 1 | C38: 包装和运输费 | D38: 0.02 | F38: RMB | G38: pcs
A39: 3120015383 | B39: 1 | C39: 包装和运输费 | D39: 0.02 | F39: RMB | G39: pcs
... A41: 3121010327 | B41: 1 | C41: 包装和运输费 | D41: 0.01 | F41: RMB | G41: pcs

Sheet 组成件BOM
A1: 宏丰料号 | B1: 项次 | C1: 工序编号 | D1: 组装工序 | E1: 项次 | F1: 组成件料号 | G1: 组成件名称 | H1: 组成数量 | I1: 组成单位
A2: 3100280160 | E2: 1 | F2: 3100280160 | G2: AgNi10丝 | H2: 1 | I2: pcs
A3: 3100580060 | E3: 1 | F3: 3100580060 | G3: AgWC40触点 | H3: 1 | I3: pcs
A4: 3120013625 | E4: 1 | F4: 3100300038 | G4: AgNi20触点 | H4: 1 | I4: pcs
A5: 3120013625 | E5: 2 | F5: 3111380164 | G5: SPCC(Q235-B)冲件 | H5: 2 | I5: pcs
A6: 3120013626 | E6: 1 | F6: 3111450547 | G6: T2-Y冲件 | H6: 1 | I6: pcs
A7: 3120013626 | E7: 2 | F7: 3113490002 | G7: AgNi15/Ag15CuP触点 | H7: 2 | I7: pcs
A8: 3120013627 | E8: 1 | F8: 3100300027 | G8: AgNi20触点 | H8: 1 | I8: pcs
A9: 3120013627 | E9: 2 | F9: 3111360058 | G9: H85冲件 | H9: 1 | I9: pcs
A10: 3120013644 | E10: 1 | F10: 3100300027 | G10: AgNi20触点 | H10: 1 | I10: pcs
A11: 3120013644 | E11: 2 | F11: 3111360059 | G11: H85冲件(缺口) | H11: 1 | I11: pcs
A12: 3120013972 | E12: 1 | F12: 3100370075 | G12: AgSnO2(12)触点 | H12: 2 | I12: pcs
A13: 3120013972 | E13: 2 | F13: 3111360069 | G13: H85冲件 | H13: 1 | I13: pcs
... A37: 3121010327 | E37: 2 | F37: 3110520517 | G37: AgNi10/Cu触点 | H37: 1 | I37: pcs

Sheet 组成件其他费用
A1: 宏丰料号 | B1: 项次 | C1: 工序编号 | D1: 组装工序 | E1: 项次 | F1: 组成件料号 | G1: 组成件名称 | H1: 供应商编号 | I1: 供应商名称 | J1: 项次 | K1: 要素编号 | L1: 要素名称 | M1: 值 | N1: 货币 | O1: 计价单位

Sheet 组装加工费
A1: 宏丰料号 | B1: 项次 | C1: 组装工序 | D1: 组装加工费 | E1: 货币 | F1: 计价单位 | G1: 拒收率/不良率（%）

Sheet 组装加工费年降
A1: 宏丰料号 | B1: 项次 | C1: 组装工序 | D1: 年降顺序 | E1: 年降系数（%） | F1: 单次固定年降值 | G1: 货币 | H1: 计价单位 | I1: 降价次数

Sheet 电镀方案
A1: 方案编号 | B1: 版本 | C1: 项次 | D1: 电镀元素名称 | E1: 元素单价来源网站网址 | F1: 元素单价来源网站名称 | G1: 元素单价抓取规则 | H1: 电镀面积（cm2） | I1: 镀层厚度（μm） | J1: 电镀要求

Sheet 电镀费用
A1: 宏丰料号 | B1: 电镀方案编号 | C1: 版本编号 | D1: 电镀加工费 | E1: 电镀材料费 | F1: 货币 | G1: 计价单位 | H1: 不良率（%）
A2: 3120013627 | D2: 0.04 | F2: RMB | G2: pcs
A3: 3120013644 | D3: 0.04 | F3: RMB | G3: pcs
A4: 3120013972 | D4: 0.04 | F4: RMB | G4: pcs
A5: 3120013973 | D5: 0.04 | F5: RMB | G5: pcs

Sheet 单重
A1: 料号 | B1: 单重（g/pcs）

Sheet 年降系数
A1: 宏丰料号 | B1: 年降顺序 | C1: 年降系数（%/年） | D1: 单次固定年降金额 | E1: 货币 | F1: 计价单位 | G1: 降价次数
